Workbook

Sheet Cover
B2: SOLAR PV FEASIBILITY STUDY
B4: Financial Model & Summary Dashboard
B6: Project Details
B8: Client: | C8: [Enter Client Name]
B9: Location: | C9: Ouarzazate, Morocco
B10: System: | C10: 125 kWp Grid-Tied Solar PV
B11: Reference: | C11: REF-OZZ-001
B12: Analyst: | C12: [Enter Analyst Name]
B13: Date: | C13: May 2026
B14: Version: | C14: v3.1 Professional
B17: MODEL CONTENTS
B19: Cover | C19: Project overview and model navigation
B20: Inputs | C20: All editable assumptions (blue cells)
B21: Annual Cashflow | C21: 25-year project cashflow with NPV and IRR
B22: Debt & Equity | C22: Financing structure, debt service, DSCR
B23: Tax & Depreciation | C23: Corporate tax, depreciation schedule
B24: Summary | C24: Key performance indicators dashboard
B25: Sensitivity Analysis | C25: Tariff, CapEx, yield, and discount rate sensitivities
B26: Scenario Analysis | C26: Conservative / Base / Optimistic scenario comparison
B27: Monthly Production | C27: Year 1 monthly energy profile from SAM
B28: Risk Matrix | C28: Qualitative risk register with mitigation measures
B29: Charts & Dashboard | C29: Visual KPIs and chart data tables
B30: Model Checks | C30: Audit validation checks and error detection
B33: COLOUR KEY
B35: ■ Blue text | C35: Hardcoded input (user-editable assumption)
B36: ■ Green text | C36: Formula-driven output (do not edit)
B37: ■ Gold text | C37: Cross-sheet link
B39: ■ Red text | C39: Critical value / warning
B41: IMPORTANT NOTES
B43: 1. All assumptions are centralized in the 'Inputs' sheet.
B44: 2. Do not edit green cells — they contain formulas.
B45: 3. The model uses a real discount rate (excludes inflation).
B46: 4. Debt & Equity sheet assumes equal principal repayment.
B47: 5. Tax sheet assumes straight-line depreciation over 20 years.
B48: 6. Run 'Model Checks' after any assumption change.
B49: 7. All monetary values are in Euros (€) unless noted.

Sheet Inputs
B2: PROJECT INPUTS
B3: All blue values are editable assumptions — all other sheets link to this sheet
B5: Parameter | C5: Value | D5: Unit
B7: TECHNICAL PARAMETERS
B8: System Capacity | C8: 125 | D8: kWp
B9: Number of Modules | C9: 312 | D9: units
B10: Module Rating | C10: 400 | D10: Wp
B11: Annual Energy Production — Year 1 | C11: 238609 | D11: kWh/year
B12: System Performance Ratio | C12: 0.81 | D12: —
B13: System Capacity Factor | C13: 0.218 | D13: —
B14: Annual Degradation Rate | C14: 0.005 | D14: —/year
B15: Total System Losses | C15: 0.114 | D15: —
B17: FINANCIAL PARAMETERS
B18: Total Installed System Cost | C18: 68800 | D18: €
B19: Annual O&M Cost | C19: 500 | D19: €/year
B20: Electricity Tariff — Year 1 | C20: 0.26 | D20: €/kWh
B21: Annual Electricity Price Escalation | C21: 0.02 | D21: —/year
B22: Real Discount Rate | C22: 0.05 | D22: —
B23: Project Lifetime | C23: 25 | D23: years
B25: ENVIRONMENTAL PARAMETERS
B26: Grid Emission Factor (Morocco) | C26: 0.718 | D26: kg CO₂/kWh
B27: Diesel Emission Factor | C27: 2.68 | D27: kg CO₂/litre
B28: Diesel Share of Current Electricity | C28: 0.6 | D28: —
B29: Grid Share of Current Electricity | C29: 0.4 | D29: —
B31: Note: Yellow cells are key assumptions most likely to affect project viability. All formula sheets reference column C of this sheet directly.

Sheet Annual Cashflow
B2: ANNUAL CASHFLOW ANALYSIS
B3: 125 kWp Solar PV · Ouarzazate, Morocco · REF-OZZ-001
B4: Blue = inputs | Green = formula outputs | All formulas reference Inputs sheet
B6: Year | C6: Energy Production (kWh) | D6: Electricity Price (€/kWh) | E6: Gross Revenue (€) | F6: O&M Cost (€) | G6: Net Annual Benefit (€) | H6: Cumulative Net Benefit (€) | I6: Discounted Net Benefit (€) | J6: NCF incl. Capex (for IRR) | K6: Cumulative Discounted Net Benefit (€)
B7: 0 | C7: 0 | D7: 0 | E7: 0 | F7: 0 | G7: =-Inputs!C18 -> -68800 | H7: =G7 -> -68800 | I7: =G7/(1+Inputs!C22)^B7 -> -68800 | J7: =G7 -> -68800 | K7: =I7 -> -68800
B8: 1 | C8: =Inputs!C11 -> 238609 | D8: =Inputs!C20 -> 0.26 | E8: =C8*D8 -> 62038.34 | F8: =Inputs!C19 -> 500 | G8: =E8-F8 -> 61538.34 | H8: =H7+G8 -> -7261.66 | I8: =G8/(1+Inputs!C22)^B8 -> 58607.943 | J8: =G8 -> 61538.34 | K8: =K7+I8 -> -10192.057
B9: 2 | C9: =C8*(1-Inputs!$C$14) -> 237415.95 | D9: =D8*(1+Inputs!$C$21) -> 0.2652 | E9: =C9*D9 -> 62962.711 | F9: =Inputs!C19 -> 500 | G9: =E9-F9 -> 62462.711 | H9: =H8+G9 -> 55201.051 | I9: =G9/(1+Inputs!C22)^B9 -> 56655.52 | J9: =G9 -> 62462.711 | K9: =K8+I9 -> 46463.463
B10: 3 | C10: =C9*(1-Inputs!$C$14) -> 236228.88 | D10: =D9*(1+Inputs!$C$21) -> 0.270504 | E10: =C10*D10 -> 63900.856 | F10: =Inputs!C19 -> 500 | G10: =E10-F10 -> 63400.856 | H10: =H9+G10 -> 118601.91 | I10: =G10/(1+Inputs!C22)^B10 -> 54768.043 | J10: =G10 -> 63400.856 | K10: =K9+I10 -> 101231.51
B11: 4 | C11: =C10*(1-Inputs!$C$14) -> 235047.73 | D11: =D10*(1+Inputs!$C$21) -> 0.27591408 | E11: =C11*D11 -> 64852.978 | F11: =Inputs!C19 -> 500 | G11: =E11-F11 -> 64352.978 | H11: =H10+G11 -> 182954.89 | I11: =G11/(1+Inputs!C22)^B11 -> 52943.355 | J11: =G11 -> 64352.978 | K11: =K10+I11 -> 154174.86
B12: 5 | C12: =C11*(1-Inputs!$C$14) -> 233872.49 | D12: =D11*(1+Inputs!$C$21) -> 0.28143236 | E12: =C12*D12 -> 65819.288 | F12: =Inputs!C19 -> 500 | G12: =E12-F12 -> 65319.288 | H12: =H11+G12 -> 248274.17 | I12: =G12/(1+Inputs!C22)^B12 -> 51179.371 | J12: =G12 -> 65319.288 | K12: =K11+I12 -> 205354.23
B13: 6 | C13: =C12*(1-Inputs!$C$14) -> 232703.13 | D13: =D12*(1+Inputs!$C$21) -> 0.28706101 | E13: =C13*D13 -> 66799.995 | F13: =Inputs!C19 -> 500 | G13: =E13-F13 -> 66299.995 | H13: =H12+G13 -> 314574.17 | I13: =G13/(1+Inputs!C22)^B13 -> 49474.077 | J13: =G13 -> 66299.995 | K13: =K12+I13 -> 254828.31
B14: 7 | C14: =C13*(1-Inputs!$C$14) -> 231539.61 | D14: =D13*(1+Inputs!$C$21) -> 0.29280223 | E14: =C14*D14 -> 67795.315 | F14: =Inputs!C19 -> 500 | G14: =E14-F14 -> 67295.315 | H14: =H13+G14 -> 381869.48 | I14: =G14/(1+Inputs!C22)^B14 -> 47825.524 | J14: =G14 -> 67295.315 | K14: =K13+I14 -> 302653.83
B15: 8 | C15: =C14*(1-Inputs!$C$14) -> 230381.92 | D15: =D14*(1+Inputs!$C$21) -> 0.29865827 | E15: =C15*D15 -> 68805.465 | F15: =Inputs!C19 -> 500 | G15: =E15-F15 -> 68305.465 | H15: =H14+G15 -> 450174.95 | I15: =G15/(1+Inputs!C22)^B15 -> 46231.828 | J15: =G15 -> 68305.465 | K15: =K14+I15 -> 348885.66
B16: 9 | C16: =C15*(1-Inputs!$C$14) -> 229230.01 | D16: =D15*(1+Inputs!$C$21) -> 0.30463144 | E16: =C16*D16 -> 69830.667 | F16: =Inputs!C19 -> 500 | G16: =E16-F16 -> 69330.667 | H16: =H15+G16 -> 519505.62 | I16: =G16/(1+Inputs!C22)^B16 -> 44691.166 | J16: =G16 -> 69330.667 | K16: =K15+I16 -> 393576.83
B17: 10 | C17: =C16*(1-Inputs!$C$14) -> 228083.86 | D17: =D16*(1+Inputs!$C$21) -> 0.31072407 | E17: =C17*D17 -> 70871.144 | F17: =Inputs!C19 -> 500 | G17: =E17-F17 -> 70371.144 | H17: =H16+G17 -> 589876.76 | I17: =G17/(1+Inputs!C22)^B17 -> 43201.778 | J17: =G17 -> 70371.144 | K17: =K16+I17 -> 436778.6
B18: 11 | C18: =C17*(1-Inputs!$C$14) -> 226943.44 | D18: =D17*(1+Inputs!$C$21) -> 0.31693855 | E18: =C18*D18 -> 71927.124 | F18: =Inputs!C19 -> 500 | G18: =E18-F18 -> 71427.124 | H18: =H17+G18 -> 661303.88 | I18: =G18/(1+Inputs!C22)^B18 -> 41761.96 | J18: =G18 -> 71427.124 | K18: =K17+I18 -> 478540.56
B19: 12 | C19: =C18*(1-Inputs!$C$14) -> 225808.72 | D19: =D18*(1+Inputs!$C$21) -> 0.32327732 | E19: =C19*D19 -> 72998.838 | F19: =Inputs!C19 -> 500 | G19: =E19-F19 -> 72498.838 | H19: =H18+G19 -> 733802.72 | I19: =G19/(1+Inputs!C22)^B19 -> 40370.066 | J19: =G19 -> 72498.838 | K19: =K18+I19 -> 518910.63
B20: 13 | C20: =C19*(1-Inputs!$C$14) -> 224679.68 | D20: =D19*(1+Inputs!$C$21) -> 0.32974287 | E20: =C20*D20 -> 74086.521 | F20: =Inputs!C19 -> 500 | G20: =E20-F20 -> 73586.521 | H20: =H19+G20 -> 807389.24 | I20: =G20/(1+Inputs!C22)^B20 -> 39024.503 | J20: =G20 -> 73586.521 | K20: =K19+I20 -> 557935.13
B21: 14 | C21: =C20*(1-Inputs!$C$14) -> 223556.28 | D21: =D20*(1+Inputs!$C$21) -> 0.33633772 | E21: =C21*D21 -> 75190.41 | F21: =Inputs!C19 -> 500 | G21: =E21-F21 -> 74690.41 | H21: =H20+G21 -> 882079.65 | I21: =G21/(1+Inputs!C22)^B21 -> 37723.732 | J21: =G21 -> 74690.41 | K21: =K20+I21 -> 595658.87
B22: 15 | C22: =C21*(1-Inputs!$C$14) -> 222438.5 | D22: =D21*(1+Inputs!$C$21) -> 0.34306448 | E22: =C22*D22 -> 76310.747 | F22: =Inputs!C19 -> 500 | G22: =E22-F22 -> 75810.747 | H22: =H21+G22 -> 957890.4 | I22: =G22/(1+Inputs!C22)^B22 -> 36466.265 | J22: =G22 -> 75810.747 | K22: =K21+I22 -> 632125.13
B23: 16 | C23: =C22*(1-Inputs!$C$14) -> 221326.3 | D23: =D22*(1+Inputs!$C$21) -> 0.34992577 | E23: =C23*D23 -> 77447.777 | F23: =Inputs!C19 -> 500 | G23: =E23-F23 -> 76947.777 | H23: =H22+G23 -> 1034838.2 | I23: =G23/(1+Inputs!C22)^B23 -> 35250.663 | J23: =G23 -> 76947.777 | K23: =K22+I23 -> 667375.79
B24: 17 | C24: =C23*(1-Inputs!$C$14) -> 220219.67 | D24: =D23*(1+Inputs!$C$21) -> 0.35692428 | E24: =C24*D24 -> 78601.749 | F24: =Inputs!C19 -> 500 | G24: =E24-F24 -> 78101.749 | H24: =H23+G24 -> 1112939.9 | I24: =G24/(1+Inputs!C22)^B24 -> 34075.534 | J24: =G24 -> 78101.749 | K24: =K23+I24 -> 701451.33
B25: 18 | C25: =C24*(1-Inputs!$C$14) -> 219118.57 | D25: =D24*(1+Inputs!$C$21) -> 0.36406277 | E25: =C25*D25 -> 79772.915 | F25: =Inputs!C19 -> 500 | G25: =E25-F25 -> 79272.915 | H25: =H24+G25 -> 1192212.8 | I25: =G25/(1+Inputs!C22)^B25 -> 32939.533 | J25: =G25 -> 79272.915 | K25: =K24+I25 -> 734390.86
B26: 19 | C26: =C25*(1-Inputs!$C$14) -> 218022.98 | D26: =D25*(1+Inputs!$C$21) -> 0.37134402 | E26: =C26*D26 -> 80961.531 | F26: =Inputs!C19 -> 500 | G26: =E26-F26 -> 80461.531 | H26: =H25+G26 -> 1272674.4 | I26: =G26/(1+Inputs!C22)^B26 -> 31841.36 | J26: =G26 -> 80461.531 | K26: =K25+I26 -> 766232.22
B27: 20 | C27: =C26*(1-Inputs!$C$14) -> 216932.87 | D27: =D26*(1+Inputs!$C$21) -> 0.3787709 | E27: =C27*D27 -> 82167.858 | F27: =Inputs!C19 -> 500 | G27: =E27-F27 -> 81667.858 | H27: =H26+G27 -> 1354342.2 | I27: =G27/(1+Inputs!C22)^B27 -> 30779.757 | J27: =G27 -> 81667.858 | K27: =K26+I27 -> 797011.98
B28: 21 | C28: =C27*(1-Inputs!$C$14) -> 215848.2 | D28: =D27*(1+Inputs!$C$21) -> 0.38634632 | E28: =C28*D28 -> 83392.159 | F28: =Inputs!C19 -> 500 | G28: =E28-F28 -> 82892.159 | H28: =H27+G28 -> 1437234.4 | I28: =G28/(1+Inputs!C22)^B28 -> 29753.508 | J28: =G28 -> 82892.159 | K28: =K27+I28 -> 826765.49
B29: 22 | C29: =C28*(1-Inputs!$C$14) -> 214768.96 | D29: =D28*(1+Inputs!$C$21) -> 0.39407325 | E29: =C29*D29 -> 84634.702 | F29: =Inputs!C19 -> 500 | G29: =E29-F29 -> 84134.702 | H29: =H28+G29 -> 1521369.1 | I29: =G29/(1+Inputs!C22)^B29 -> 28761.437 | J29: =G29 -> 84134.702 | K29: =K28+I29 -> 855526.92
B30: 23 | C30: =C29*(1-Inputs!$C$14) -> 213695.12 | D30: =D29*(1+Inputs!$C$21) -> 0.40195471 | E30: =C30*D30 -> 85895.759 | F30: =Inputs!C19 -> 500 | G30: =E30-F30 -> 85395.759 | H30: =H29+G30 -> 1606764.8 | I30: =G30/(1+Inputs!C22)^B30 -> 27802.409 | J30: =G30 -> 85395.759 | K30: =K29+I30 -> 883329.33
B31: 24 | C31: =C30*(1-Inputs!$C$14) -> 212626.64 | D31: =D30*(1+Inputs!$C$21) -> 0.40999381 | E31: =C31*D31 -> 87175.606 | F31: =Inputs!C19 -> 500 | G31: =E31-F31 -> 86675.606 | H31: =H30+G31 -> 1693440.5 | I31: =G31/(1+Inputs!C22)^B31 -> 26875.324 | J31: =G31 -> 86675.606 | K31: =K30+I31 -> 910204.66
B32: 25 | C32: =C31*(1-Inputs!$C$14) -> 211563.51 | D32: =D31*(1+Inputs!$C$21) -> 0.41819368 | E32: =C32*D32 -> 88474.523 | F32: =Inputs!C19 -> 500 | G32: =E32-F32 -> 87974.523 | H32: =H31+G32 -> 1781415 | I32: =G32/(1+Inputs!C22)^B32 -> 25979.12 | J32: =G32 -> 87974.523 | K32: =K31+I32 -> 936183.78
B33: TOTALS / NPV | E33: =SUM(E8:E32) -> 1862715 | G33: =SUM(G8:G32) -> 1850215 | H33: =H32 -> 1781415 | I33: =SUM(I7:I32) -> 936183.78 | J33: =SUM(J7:J32) -> 1781415
B34: Project NPV (€) | D34: =I33 -> 936183.78
B35: Helper — capex negative (for IRR formula): | C35: =-Inputs!C18 -> -68800

Sheet Debt & Equity
B2: DEBT & EQUITY FINANCING
B3: 125 kWp Solar PV · Ouarzazate, Morocco · REF-OZZ-001
B5: FINANCING PARAMETERS
B7: Debt Share (% of CapEx) | C7: 0.7 | D7: —
B8: Equity Share (% of CapEx) | C8: 0.3 | D8: —
B9: Loan Interest Rate (nominal) | C9: 0.06 | D9: —/year
B10: Loan Tenor | C10: 15 | D10: years
B11: Debt Service Reserve (months) | C11: 6 | D11: months
B12: Upfront Fee (% of loan) | C12: 0.015 | D12: —
B13: Commitment Fee (% of undrawn) | C13: 0.005 | D13: —
B15: FINANCING STRUCTURE
B16: Total Project Cost (€) | C16: =Inputs!C18 -> 68800
B17: Total Debt Amount (€) | C17: =C16*C7 -> 48160
B18: Total Equity Amount (€) | C18: =C16*C8 -> 20640
B19: Upfront Fee (€) | C19: =C17*C9 -> 2889.6
B20: Total Financing Required (€) | C20: =C16+C19 -> 71689.6
B21: Equity as % of Total | C21: =C17/C20 -> 0.67178503
B23: DEBT SERVICE SCHEDULE
B25: Year | C25: Opening Balance (€) | D25: Principal (€) | E25: Interest (€) | F25: Total Debt Service (€) | G25: DSCR | H25: CFADS (€)
B26: 1 | C26: =IF(B26=1,C17,C25-D25) -> 48160 | D26: =IF(B26<=$C$10,C17/$C$10,0) -> 3210.6667 | E26: =C26*$C$9 -> 2889.6 | F26: =D26+E26 -> 6100.2667 | G26: =IF(F26=0,"N/A",'Annual Cashflow'!G32/F26) -> 14.421422 | H26: ='Annual Cashflow'!G32 -> 87974.523
B27: 2 | C27: =IF(B27=1,C17,C26-D26) -> 44949.333 | D27: =IF(B27<=$C$10,C17/$C$10,0) -> 3210.6667 | E27: =C27*$C$9 -> 2696.96 | F27: =D27+E27 -> 5907.6267 | G27: =IF(F27=0,"N/A",'Annual Cashflow'!G33/F27) -> 313.19091 | H27: ='Annual Cashflow'!G33 -> 1850215
B28: 3 | C28: =IF(B28=1,C17,C27-D27) -> 41738.667 | D28: =IF(B28<=$C$10,C17/$C$10,0) -> 3210.6667 | E28: =C28*$C$9 -> 2504.32 | F28: =D28+E28 -> 5714.9867 | G28: =IF(F28=0,"N/A",'Annual Cashflow'!G34/F28) -> 0 | H28: ='Annual Cashflow'!G34 -> 0
B29: 4 | C29: =IF(B29=1,C17,C28-D28) -> 38528 | D29: =IF(B29<=$C$10,C17/$C$10,0) -> 3210.6667 | E29: =C29*$C$9 -> 2311.68 | F29: =D29+E29 -> 5522.3467 | G29: =IF(F29=0,"N/A",'Annual Cashflow'!G35/F29) -> 0 | H29: ='Annual Cashflow'!G35 -> 0
B30: 5 | C30: =IF(B30=1,C17,C29-D29) -> 35317.333 | D30: =IF(B30<=$C$10,C17/$C$10,0) -> 3210.6667 | E30: =C30*$C$9 -> 2119.04 | F30: =D30+E30 -> 5329.7067 | G30: =IF(F30=0,"N/A",'Annual Cashflow'!G36/F30) -> 0 | H30: ='Annual Cashflow'!G36 -> 0
B31: 6 | C31: =IF(B31=1,C17,C30-D30) -> 32106.667 | D31: =IF(B31<=$C$10,C17/$C$10,0) -> 3210.6667 | E31: =C31*$C$9 -> 1926.4 | F31: =D31+E31 -> 5137.0667 | G31: =IF(F31=0,"N/A",'Annual Cashflow'!G37/F31) -> 0 | H31: ='Annual Cashflow'!G37 -> 0
B32: 7 | C32: =IF(B32=1,C17,C31-D31) -> 28896 | D32: =IF(B32<=$C$10,C17/$C$10,0) -> 3210.6667 | E32: =C32*$C$9 -> 1733.76 | F32: =D32+E32 -> 4944.4267 | G32: =IF(F32=0,"N/A",'Annual Cashflow'!G38/F32) -> 0 | H32: ='Annual Cashflow'!G38 -> 0
B33: 8 | C33: =IF(B33=1,C17,C32-D32) -> 25685.333 | D33: =IF(B33<=$C$10,C17/$C$10,0) -> 3210.6667 | E33: =C33*$C$9 -> 1541.12 | F33: =D33+E33 -> 4751.7867 | G33: =IF(F33=0,"N/A",'Annual Cashflow'!G39/F33) -> 0 | H33: ='Annual Cashflow'!G39 -> 0
B34: 9 | C34: =IF(B34=1,C17,C33-D33) -> 22474.667 | D34: =IF(B34<=$C$10,C17/$C$10,0) -> 3210.6667 | E34: =C34*$C$9 -> 1348.48 | F34: =D34+E34 -> 4559.1467 | G34: =IF(F34=0,"N/A",'Annual Cashflow'!G40/F34) -> 0 | H34: ='Annual Cashflow'!G40 -> 0
B35: 10 | C35: =IF(B35=1,C17,C34-D34) -> 19264 | D35: =IF(B35<=$C$10,C17/$C$10,0) -> 3210.6667 | E35: =C35*$C$9 -> 1155.84 | F35: =D35+E35 -> 4366.5067 | G35: =IF(F35=0,"N/A",'Annual Cashflow'!G41/F35) -> 0 | H35: ='Annual Cashflow'!G41 -> 0
B36: 11 | C36: =IF(B36=1,C17,C35-D35) -> 16053.333 | D36: =IF(B36<=$C$10,C17/$C$10,0) -> 3210.6667 | E36: =C36*$C$9 -> 963.2 | F36: =D36+E36 -> 4173.8667 | G36: =IF(F36=0,"N/A",'Annual Cashflow'!G42/F36) -> 0 | H36: ='Annual Cashflow'!G42 -> 0
B37: 12 | C37: =IF(B37=1,C17,C36-D36) -> 12842.667 | D37: =IF(B37<=$C$10,C17/$C$10,0) -> 3210.6667 | E37: =C37*$C$9 -> 770.56 | F37: =D37+E37 -> 3981.2267 | G37: =IF(F37=0,"N/A",'Annual Cashflow'!G43/F37) -> 0 | H37: ='Annual Cashflow'!G43 -> 0
B38: 13 | C38: =IF(B38=1,C17,C37-D37) -> 9632 | D38: =IF(B38<=$C$10,C17/$C$10,0) -> 3210.6667 | E38: =C38*$C$9 -> 577.92 | F38: =D38+E38 -> 3788.5867 | G38: =IF(F38=0,"N/A",'Annual Cashflow'!G44/F38) -> 0 | H38: ='Annual Cashflow'!G44 -> 0
B39: 14 | C39: =IF(B39=1,C17,C38-D38) -> 6421.3333 | D39: =IF(B39<=$C$10,C17/$C$10,0) -> 3210.6667 | E39: =C39*$C$9 -> 385.28 | F39: =D39+E39 -> 3595.9467 | G39: =IF(F39=0,"N/A",'Annual Cashflow'!G45/F39) -> 0 | H39: ='Annual Cashflow'!G45 -> 0
B40: 15 | C40: =IF(B40=1,C17,C39-D39) -> 3210.6667 | D40: =IF(B40<=$C$10,C17/$C$10,0) -> 3210.6667 | E40: =C40*$C$9 -> 192.64 | F40: =D40+E40 -> 3403.3067 | G40: =IF(F40=0,"N/A",'Annual Cashflow'!G46/F40) -> 0 | H40: ='Annual Cashflow'!G46 -> 0
B42: Minimum DSCR | C42: =MIN(G26:G40) -> 0
B43: Average DSCR | C43: =AVERAGE(G26:G40) -> 21.840822
B44: LLCR (Loan Life Coverage Ratio) | C44: =NPV(C9,H26:H40)/C17 -> 35.915274

Sheet Tax & Depreciation
B2: TAX & DEPRECIATION ANALYSIS
B3: 125 kWp Solar PV · Ouarzazate, Morocco · REF-OZZ-001
B5: TAX PARAMETERS
B7: Corporate Tax Rate | C7: 0.2 | D7: —
B8: Depreciation Method | C8: Straight-Line
B9: Depreciation Period | C9: 20 | D9: years
B10: Tax Holiday (years) | C10: 0 | D10: years
B11: VAT Rate | C11: 0.2 | D11: —
B12: VAT Recoverable on CapEx | C12: YES
B15: TAX SCHEDULE
B17: Year | C17: Gross Revenue (€) | D17: O&M Cost (€) | E17: Depreciation (€) | F17: Interest (€) | G17: Taxable Income (€) | H17: Tax Payable (€) | I17: Net Income (€)
B18: 1 | C18: ='Annual Cashflow'!E24 -> 78601.749 | D18: ='Annual Cashflow'!F24 -> 500 | E18: =IF(B18<=$C$9,Inputs!C18/$C$9,0) -> 3440 | F18: =IF(B18<=15,'Debt & Equity'!E26,0) -> 2889.6 | G18: =MAX(C18-D18-E18-F18,0) -> 71772.149 | H18: =G18*$C$7 -> 14354.43 | I18: =C18-D18-E18-F18-H18 -> 57417.719
B19: 2 | C19: ='Annual Cashflow'!E25 -> 79772.915 | D19: ='Annual Cashflow'!F25 -> 500 | E19: =IF(B19<=$C$9,Inputs!C18/$C$9,0) -> 3440 | F19: =IF(B19<=15,'Debt & Equity'!E27,0) -> 2696.96 | G19: =MAX(C19-D19-E19-F19,0) -> 73135.955 | H19: =G19*$C$7 -> 14627.191 | I19: =C19-D19-E19-F19-H19 -> 58508.764
B20: 3 | C20: ='Annual Cashflow'!E26 -> 80961.531 | D20: ='Annual Cashflow'!F26 -> 500 | E20: =IF(B20<=$C$9,Inputs!C18/$C$9,0) -> 3440 | F20: =IF(B20<=15,'Debt & Equity'!E28,0) -> 2504.32 | G20: =MAX(C20-D20-E20-F20,0) -> 74517.211 | H20: =G20*$C$7 -> 14903.442 | I20: =C20-D20-E20-F20-H20 -> 59613.769
B21: 4 | C21: ='Annual Cashflow'!E27 -> 82167.858 | D21: ='Annual Cashflow'!F27 -> 500 | E21: =IF(B21<=$C$9,Inputs!C18/$C$9,0) -> 3440 | F21: =IF(B21<=15,'Debt & Equity'!E29,0) -> 2311.68 | G21: =MAX(C21-D21-E21-F21,0) -> 75916.178 | H21: =G21*$C$7 -> 15183.236 | I21: =C21-D21-E21-F21-H21 -> 60732.942
B22: 5 | C22: ='Annual Cashflow'!E28 -> 83392.159 | D22: ='Annual Cashflow'!F28 -> 500 | E22: =IF(B22<=$C$9,Inputs!C18/$C$9,0) -> 3440 | F22: =IF(B22<=15,'Debt & Equity'!E30,0) -> 2119.04 | G22: =MAX(C22-D22-E22-F22,0) -> 77333.119 | H22: =G22*$C$7 -> 15466.624 | I22: =C22-D22-E22-F22-H22 -> 61866.495
B23: 6 | C23: ='Annual Cashflow'!E29 -> 84634.702 | D23: ='Annual Cashflow'!F29 -> 500 | E23: =IF(B23<=$C$9,Inputs!C18/$C$9,0) -> 3440 | F23: =IF(B23<=15,'Debt & Equity'!E31,0) -> 1926.4 | G23: =MAX(C23-D23-E23-F23,0) -> 78768.302 | H23: =G23*$C$7 -> 15753.66 | I23: =C23-D23-E23-F23-H23 -> 63014.642
B24: 7 | C24: ='Annual Cashflow'!E30 -> 85895.759 | D24: ='Annual Cashflow'!F30 -> 500 | E24: =IF(B24<=$C$9,Inputs!C18/$C$9,0) -> 3440 | F24: =IF(B24<=15,'Debt & Equity'!E32,0) -> 1733.76 | G24: =MAX(C24-D24-E24-F24,0) -> 80221.999 | H24: =G24*$C$7 -> 16044.4 | I24: =C24-D24-E24-F24-H24 -> 64177.6
B25: 8 | C25: ='Annual Cashflow'!E31 -> 87175.606 | D25: ='Annual Cashflow'!F31 -> 500 | E25: =IF(B25<=$C$9,Inputs!C18/$C$9,0) -> 3440 | F25: =IF(B25<=15,'Debt & Equity'!E33,0) -> 1541.12 | G25: =MAX(C25-D25-E25-F25,0) -> 81694.486 | H25: =G25*$C$7 -> 16338.897 | I25: =C25-D25-E25-F25-H25 -> 65355.589
B26: 9 | C26: ='Annual Cashflow'!E32 -> 88474.523 | D26: ='Annual Cashflow'!F32 -> 500 | E26: =IF(B26<=$C$9,Inputs!C18/$C$9,0) -> 3440 | F26: =IF(B26<=15,'Debt & Equity'!E34,0) -> 1348.48 | G26: =MAX(C26-D26-E26-F26,0) -> 83186.043 | H26: =G26*$C$7 -> 16637.209 | I26: =C26-D26-E26-F26-H26 -> 66548.834
B27: 10 | C27: ='Annual Cashflow'!E33 -> 1862715 | D27: ='Annual Cashflow'!F33 -> 0 | E27: =IF(B27<=$C$9,Inputs!C18/$C$9,0) -> 3440 | F27: =IF(B27<=15,'Debt & Equity'!E35,0) -> 1155.84 | G27: =MAX(C27-D27-E27-F27,0) -> 1858119.1 | H27: =G27*$C$7 -> 371623.83 | I27: =C27-D27-E27-F27-H27 -> 1486495.3
B28: 11 | C28: ='Annual Cashflow'!E34 -> 0 | D28: ='Annual Cashflow'!F34 -> 0 | E28: =IF(B28<=$C$9,Inputs!C18/$C$9,0) -> 3440 | F28: =IF(B28<=15,'Debt & Equity'!E36,0) -> 963.2 | G28: =MAX(C28-D28-E28-F28,0) -> 0 | H28: =G28*$C$7 -> 0 | I28: =C28-D28-E28-F28-H28 -> -4403.2
B29: 12 | C29: ='Annual Cashflow'!E35 -> 0 | D29: ='Annual Cashflow'!F35 -> 0 | E29: =IF(B29<=$C$9,Inputs!C18/$C$9,0) -> 3440 | F29: =IF(B29<=15,'Debt & Equity'!E37,0) -> 770.56 | G29: =MAX(C29-D29-E29-F29,0) -> 0 | H29: =G29*$C$7 -> 0 | I29: =C29-D29-E29-F29-H29 -> -4210.56
B30: 13 | C30: ='Annual Cashflow'!E36 -> 0 | D30: ='Annual Cashflow'!F36 -> 0 | E30: =IF(B30<=$C$9,Inputs!C18/$C$9,0) -> 3440 | F30: =IF(B30<=15,'Debt & Equity'!E38,0) -> 577.92 | G30: =MAX(C30-D30-E30-F30,0) -> 0 | H30: =G30*$C$7 -> 0 | I30: =C30-D30-E30-F30-H30 -> -4017.92
B31: 14 | C31: ='Annual Cashflow'!E37 -> 0 | D31: ='Annual Cashflow'!F37 -> 0 | E31: =IF(B31<=$C$9,Inputs!C18/$C$9,0) -> 3440 | F31: =IF(B31<=15,'Debt & Equity'!E39,0) -> 385.28 | G31: =MAX(C31-D31-E31-F31,0) -> 0 | H31: =G31*$C$7 -> 0 | I31: =C31-D31-E31-F31-H31 -> -3825.28
B32: 15 | C32: ='Annual Cashflow'!E38 -> 0 | D32: ='Annual Cashflow'!F38 -> 0 | E32: =IF(B32<=$C$9,Inputs!C18/$C$9,0) -> 3440 | F32: =IF(B32<=15,'Debt & Equity'!E40,0) -> 192.64 | G32: =MAX(C32-D32-E32-F32,0) -> 0 | H32: =G32*$C$7 -> 0 | I32: =C32-D32-E32-F32-H32 -> -3632.64
B33: 16 | C33: ='Annual Cashflow'!E39 -> 0 | D33: ='Annual Cashflow'!F39 -> 0 | E33: =IF(B33<=$C$9,Inputs!C18/$C$9,0) -> 3440 | F33: =IF(B33<=15,'Debt & Equity'!E41,0) -> 0 | G33: =MAX(C33-D33-E33-F33,0) -> 0 | H33: =G33*$C$7 -> 0 | I33: =C33-D33-E33-F33-H33 -> -3440
B34: 17 | C34: ='Annual Cashflow'!E40 -> 0 | D34: ='Annual Cashflow'!F40 -> 0 | E34: =IF(B34<=$C$9,Inputs!C18/$C$9,0) -> 3440 | F34: =IF(B34<=15,'Debt & Equity'!E42,0) -> 0 | G34: =MAX(C34-D34-E34-F34,0) -> 0 | H34: =G34*$C$7 -> 0 | I34: =C34-D34-E34-F34-H34 -> -3440
B35: 18 | C35: ='Annual Cashflow'!E41 -> 0 | D35: ='Annual Cashflow'!F41 -> 0 | E35: =IF(B35<=$C$9,Inputs!C18/$C$9,0) -> 3440 | F35: =IF(B35<=15,'Debt & Equity'!E43,0) -> 0 | G35: =MAX(C35-D35-E35-F35,0) -> 0 | H35: =G35*$C$7 -> 0 | I35: =C35-D35-E35-F35-H35 -> -3440
B36: 19 | C36: ='Annual Cashflow'!E42 -> 0 | D36: ='Annual Cashflow'!F42 -> 0 | E36: =IF(B36<=$C$9,Inputs!C18/$C$9,0) -> 3440 | F36: =IF(B36<=15,'Debt & Equity'!E44,0) -> 0 | G36: =MAX(C36-D36-E36-F36,0) -> 0 | H36: =G36*$C$7 -> 0 | I36: =C36-D36-E36-F36-H36 -> -3440
B37: 20 | C37: ='Annual Cashflow'!E43 -> 0 | D37: ='Annual Cashflow'!F43 -> 0 | E37: =IF(B37<=$C$9,Inputs!C18/$C$9,0) -> 3440 | F37: =IF(B37<=15,'Debt & Equity'!E45,0) -> 0 | G37: =MAX(C37-D37-E37-F37,0) -> 0 | H37: =G37*$C$7 -> 0 | I37: =C37-D37-E37-F37-H37 -> -3440
B38: 21 | C38: ='Annual Cashflow'!E44 -> 0 | D38: ='Annual Cashflow'!F44 -> 0 | E38: =IF(B38<=$C$9,Inputs!C18/$C$9,0) -> 0 | F38: =IF(B38<=15,'Debt & Equity'!E46,0) -> 0 | G38: =MAX(C38-D38-E38-F38,0) -> 0 | H38: =G38*$C$7 -> 0 | I38: =C38-D38-E38-F38-H38 -> 0
B39: 22 | C39: ='Annual Cashflow'!E45 -> 0 | D39: ='Annual Cashflow'!F45 -> 0 | E39: =IF(B39<=$C$9,Inputs!C18/$C$9,0) -> 0 | F39: =IF(B39<=15,'Debt & Equity'!E47,0) -> 0 | G39: =MAX(C39-D39-E39-F39,0) -> 0 | H39: =G39*$C$7 -> 0 | I39: =C39-D39-E39-F39-H39 -> 0
B40: 23 | C40: ='Annual Cashflow'!E46 -> 0 | D40: ='Annual Cashflow'!F46 -> 0 | E40: =IF(B40<=$C$9,Inputs!C18/$C$9,0) -> 0 | F40: =IF(B40<=15,'Debt & Equity'!E48,0) -> 0 | G40: =MAX(C40-D40-E40-F40,0) -> 0 | H40: =G40*$C$7 -> 0 | I40: =C40-D40-E40-F40-H40 -> 0
B41: 24 | C41: ='Annual Cashflow'!E47 -> 0 | D41: ='Annual Cashflow'!F47 -> 0 | E41: =IF(B41<=$C$9,Inputs!C18/$C$9,0) -> 0 | F41: =IF(B41<=15,'Debt & Equity'!E49,0) -> 0 | G41: =MAX(C41-D41-E41-F41,0) -> 0 | H41: =G41*$C$7 -> 0 | I41: =C41-D41-E41-F41-H41 -> 0
B42: 25 | C42: ='Annual Cashflow'!E48 -> 0 | D42: ='Annual Cashflow'!F48 -> 0 | E42: =IF(B42<=$C$9,Inputs!C18/$C$9,0) -> 0 | F42: =IF(B42<=15,'Debt & Equity'!E50,0) -> 0 | G42: =MAX(C42-D42-E42-F42,0) -> 0 | H42: =G42*$C$7 -> 0 | I42: =C42-D42-E42-F42-H42 -> 0
B44: TOTALS | C44: =SUM(C18:C42) -> 2613791.8 | D44: =SUM(D18:D42) -> 4500 | E44: =SUM(E18:E42) -> 68800 | F44: =SUM(F18:F42) -> 23116.8 | G44: =SUM(G18:G42) -> 2554664.6 | H44: =SUM(H18:H42) -> 510932.92 | I44: =SUM(I18:I42) -> 2006442.1
B46: KEY TAX METRICS
B47: Total Tax Paid (25 years) | C47: =H44 -> 510932.92
B48: Total Depreciation Claimed | C48: =E44 -> 68800
...

Sheet Summary
B2: PROJECT SUMMARY DASHBOARD
B3: 125 kWp Solar PV · Ouarzazate, Morocco · REF-OZZ-001 · v2.0
B5: TECHNICAL RESULTS
B6: System Capacity | C6: =Inputs!C8&" kWp" -> 125 kWp
B7: Number of Modules | C7: =Inputs!C9&" units" -> 312 units
B8: Annual Energy Production — Year 1 | C8: =TEXT(Inputs!C11,"#,##0")&" kWh" -> 238609,0 kWh
B9: 25-Year Total Energy Production | C9: =TEXT(SUMPRODUCT(Inputs!C11*(1-Inputs!C14)^(ROW(INDIRECT("1:25"))-1)),"#,##0")&" kWh" -> 5620662,010 kWh
B10: Capacity Factor | C10: =Inputs!C13 -> 0.218
B11: Performance Ratio | C11: =Inputs!C12 -> 0.81
B13: FINANCIAL RESULTS
B14: Total Installed System Cost | C14: =Inputs!C18 -> 68800
B15: Year 1 Gross Revenue | C15: ='Annual Cashflow'!E7 -> 0
B16: Year 1 Net Annual Savings | C16: ='Annual Cashflow'!G7 -> -68800
B17: Simple Payback Period | C17: =Inputs!C18/'Annual Cashflow'!G7 -> -1
B18: Discounted Payback Period | C18: =IFERROR(MATCH(TRUE,'Annual Cashflow'!K7:K32>=0,0)-1+ABS(INDEX('Annual Cashflow'!K7:K32,MATCH(TRUE,'Annual Cashflow'!K7:K32>=0,0)-1))/INDEX('Annual Cashflow'!I7:I32,MATCH(TRUE,'Annual Cashflow'!K7:K32>=0,0)),"N/A") -> N/A
B19: Net Present Value (25 years) | C19: =NPV(Inputs!C22,'Annual Cashflow'!G7:G31)-Inputs!C18 -> 798061.58
B20: Internal Rate of Return (IRR) | C20: =IRR('Annual Cashflow'!J7:J32) -> 0.90947156
B21: 25-Year Cumulative Net Benefit | C21: ='Annual Cashflow'!H31 -> 1693440.5
B22: Benefit-Cost Ratio (BCR) | C22: =NPV(Inputs!C22,'Annual Cashflow'!G8:G32)/Inputs!C18 -> 14.607322
B23: 25-Year Gross Savings | C23: ='Annual Cashflow'!G32 -> 87974.523
B24: 25-Year Investment Multiple (MOIC) | C24: ='Annual Cashflow'!H31/Inputs!C18 -> 24.61396
B25: Levelized Cost of Energy (LCOE) | C25: =(Inputs!C18+SUMPRODUCT(Inputs!C19/(1+Inputs!C22)^ROW(INDIRECT("1:25"))))/SUMPRODUCT(Inputs!C11*(1-Inputs!C14)^(ROW(INDIRECT("1:25"))-1)/(1+Inputs!C22)^ROW(INDIRECT("1:25"))) -> 0.023642256
B26: Current Blended Tariff | C26: =(Inputs!C20-C23)/Inputs!C20 -> -338362.55
B27: LCOE vs. Blended Tariff (% reduction) | C27: =1-C23/Inputs!C20 -> -338362.55
B29: ENVIRONMENTAL RESULTS
B30: Grid Emission Factor (Morocco) | C30: =Inputs!C26&" kg CO₂/kWh" -> 0,718 kg CO₂/kWh
B31: Annual CO₂ Savings — Grid | C31: =Inputs!C11*Inputs!C29*Inputs!C26/1000 -> 68.528505
B32: Annual CO₂ Savings — Diesel | C32: =Inputs!C11*Inputs!C28/(3.08)*Inputs!C27/1000 -> 124.57249
B33: Total Annual CO₂ Savings — Year 1 | C33: =C31+C32 -> 193.101
B34: Equivalent Trees Planted — Annual | C34: =ROUND(C31/0.021,0)&" trees" -> 3263 trees
B35: Lifetime CO₂ Savings per € Invested | C35: =C32/Inputs!C18&" tonnes/€" -> 0,00181064667019027 tonnes/€
B36: 25-Year Lifetime CO₂ Savings | C36: {=SUMPRODUCT((C31+C32)*(1-Inputs!C14)^(ROW(INDIRECT("1:25"))-1))} -> 4548.6777
B37: Equivalent Passenger Cars — Annual | C37: =ROUND(C31/2.01,0)&" cars" -> 34 cars

Sheet Sensitivity Analysis
B2: SENSITIVITY ANALYSIS
B3: Impact of key variable changes on project returns (all other inputs held at base case)
B4: Note: Values below are calculated independently of the main cashflow sheet, using embedded formulas for each scenario.
B6: Scenario | C6: Payback (yrs) | D6: NPV (€) | E6: MOIC (x) | F6: IRR (%)
B7: A — ELECTRICITY TARIFF SENSITIVITY
B8: Tariff −20% (€0.208/kWh) | C8: =Inputs!C18/(Inputs!C11*Inputs!C20*0.8-Inputs!C19) -> 1.4003472 | D8: =SUMPRODUCT((Inputs!C11*(1-Inputs!C14)^(ROW(INDIRECT("1:25"))-1)*Inputs!C20*0.8*(1+Inputs!C21)^(ROW(INDIRECT("1:25"))-1)-Inputs!C19)/(1+Inputs!C22)^ROW(INDIRECT("1:25")))-Inputs!C18 -> 733777.63 | E8: =SUMPRODUCT((Inputs!C11*(1-Inputs!C14)^(ROW(INDIRECT("1:25"))-1)*Inputs!C20*0.8*(1+Inputs!C21)^(ROW(INDIRECT("1:25"))-1)-Inputs!C19))/Inputs!C18 -> 21.47779
B9: Tariff −10% (€0.234/kWh) | C9: =Inputs!C18/(Inputs!C11*Inputs!C20*0.9-Inputs!C19) -> 1.2433471 | D9: =SUMPRODUCT((Inputs!C11*(1-Inputs!C14)^(ROW(INDIRECT("1:25"))-1)*Inputs!C20*0.9*(1+Inputs!C21)^(ROW(INDIRECT("1:25"))-1)-Inputs!C19)/(1+Inputs!C22)^ROW(INDIRECT("1:25")))-Inputs!C18 -> 834980.7 | E9: =SUMPRODUCT((Inputs!C11*(1-Inputs!C14)^(ROW(INDIRECT("1:25"))-1)*Inputs!C20*0.9*(1+Inputs!C21)^(ROW(INDIRECT("1:25"))-1)-Inputs!C19))/Inputs!C18 -> 24.185225
B10: Base Case (€0.260/kWh) | C10: =Inputs!C18/(Inputs!C11*Inputs!C20-Inputs!C19) -> 1.1180022 | D10: =SUMPRODUCT((Inputs!C11*(1-Inputs!C14)^(ROW(INDIRECT("1:25"))-1)*Inputs!C20*(1+Inputs!C21)^(ROW(INDIRECT("1:25"))-1)-Inputs!C19)/(1+Inputs!C22)^ROW(INDIRECT("1:25")))-Inputs!C18 -> 936183.78 | E10: =SUMPRODUCT((Inputs!C11*(1-Inputs!C14)^(ROW(INDIRECT("1:25"))-1)*Inputs!C20*(1+Inputs!C21)^(ROW(INDIRECT("1:25"))-1)-Inputs!C19))/Inputs!C18 -> 26.89266
B11: Tariff +10% (€0.286/kWh) | C11: =Inputs!C18/(Inputs!C11*Inputs!C20*1.1-Inputs!C19) -> 1.0156155 | D11: =SUMPRODUCT((Inputs!C11*(1-Inputs!C14)^(ROW(INDIRECT("1:25"))-1)*Inputs!C20*1.1*(1+Inputs!C21)^(ROW(INDIRECT("1:25"))-1)-Inputs!C19)/(1+Inputs!C22)^ROW(INDIRECT("1:25")))-Inputs!C18 -> 1037386.9 | E11: =SUMPRODUCT((Inputs!C11*(1-Inputs!C14)^(ROW(INDIRECT("1:25"))-1)*Inputs!C20*1.1*(1+Inputs!C21)^(ROW(INDIRECT("1:25"))-1)-Inputs!C19))/Inputs!C18 -> 29.600094
B12: Tariff +20% (€0.312/kWh) | C12: =Inputs!C18/(Inputs!C11*Inputs!C20*1.2-Inputs!C19) -> 0.93040858 | D12: {=SUMPRODUCT((Inputs!C11*(1-Inputs!C14)^(ROW(INDIRECT("1:25"))-1)*Inputs!C20*1.2*(1+Inputs!C21)^(ROW(INDIRECT("1:25"))-1)-Inputs!C19)/(1+Inputs!C22)^ROW(INDIRECT("1:25")))-Inputs!C18} -> 1138589.9 | E12: =SUMPRODUCT((Inputs!C11*(1-Inputs!C14)^(ROW(INDIRECT("1:25"))-1)*Inputs!C20*1.2*(1+Inputs!C21)^(ROW(INDIRECT("1:25"))-1)-Inputs!C19))/Inputs!C18 -> 32.307529
B15: B — CAPITAL COST SENSITIVITY
B16: CapEx +30% (€89,440) | C16: =Inputs!C18*1.3/(Inputs!C11*Inputs!C20-Inputs!C19) -> 1.4534029 | D16: =SUMPRODUCT((Inputs!C11*(1-Inputs!C14)^(ROW(INDIRECT("1:25"))-1)*Inputs!C20*(1+Inputs!C21)^(ROW(INDIRECT("1:25"))-1)-Inputs!C19)/(1+Inputs!C22)^ROW(INDIRECT("1:25")))-Inputs!C18*1.3 -> 915543.78 | E16: =SUMPRODUCT((Inputs!C11*(1-Inputs!C14)^(ROW(INDIRECT("1:25"))-1)*Inputs!C20*(1+Inputs!C21)^(ROW(INDIRECT("1:25"))-1)-Inputs!C19))/(Inputs!C18*1.3) -> 20.686661
B17: CapEx +20% (€82,560) | C17: =Inputs!C18*1.2/(Inputs!C11*Inputs!C20-Inputs!C19) -> 1.3416026 | D17: =SUMPRODUCT((Inputs!C11*(1-Inputs!C14)^(ROW(INDIRECT("1:25"))-1)*Inputs!C20*(1+Inputs!C21)^(ROW(INDIRECT("1:25"))-1)-Inputs!C19)/(1+Inputs!C22)^ROW(INDIRECT("1:25")))-Inputs!C18*1.2 -> 922423.78 | E17: =SUMPRODUCT((Inputs!C11*(1-Inputs!C14)^(ROW(INDIRECT("1:25"))-1)*Inputs!C20*(1+Inputs!C21)^(ROW(INDIRECT("1:25"))-1)-Inputs!C19))/(Inputs!C18*1.2) -> 22.41055
B18: CapEx +10% (€75,680) | C18: =Inputs!C18*1.1/(Inputs!C11*Inputs!C20-Inputs!C19) -> 1.2298024 | D18: =SUMPRODUCT((Inputs!C11*(1-Inputs!C14)^(ROW(INDIRECT("1:25"))-1)*Inputs!C20*(1+Inputs!C21)^(ROW(INDIRECT("1:25"))-1)-Inputs!C19)/(1+Inputs!C22)^ROW(INDIRECT("1:25")))-Inputs!C18*1.1 -> 929303.78 | E18: =SUMPRODUCT((Inputs!C11*(1-Inputs!C14)^(ROW(INDIRECT("1:25"))-1)*Inputs!C20*(1+Inputs!C21)^(ROW(INDIRECT("1:25"))-1)-Inputs!C19))/(Inputs!C18*1.1) -> 24.447872
B19: Base Case (€68,800) | C19: =Inputs!C18/(Inputs!C11*Inputs!C20-Inputs!C19) -> 1.1180022 | D19: =SUMPRODUCT((Inputs!C11*(1-Inputs!C14)^(ROW(INDIRECT("1:25"))-1)*Inputs!C20*(1+Inputs!C21)^(ROW(INDIRECT("1:25"))-1)-Inputs!C19)/(1+Inputs!C22)^ROW(INDIRECT("1:25")))-Inputs!C18 -> 936183.78 | E19: =SUMPRODUCT((Inputs!C11*(1-Inputs!C14)^(ROW(INDIRECT("1:25"))-1)*Inputs!C20*(1+Inputs!C21)^(ROW(INDIRECT("1:25"))-1)-Inputs!C19))/(Inputs!C18*1) -> 26.89266
B20: CapEx −10% (€61,920) | C20: =Inputs!C18*0.9/(Inputs!C11*Inputs!C20-Inputs!C19) -> 1.006202 | D20: =SUMPRODUCT((Inputs!C11*(1-Inputs!C14)^(ROW(INDIRECT("1:25"))-1)*Inputs!C20*(1+Inputs!C21)^(ROW(INDIRECT("1:25"))-1)-Inputs!C19)/(1+Inputs!C22)^ROW(INDIRECT("1:25")))-Inputs!C18*0.9 -> 943063.78 | E20: =SUMPRODUCT((Inputs!C11*(1-Inputs!C14)^(ROW(INDIRECT("1:25"))-1)*Inputs!C20*(1+Inputs!C21)^(ROW(INDIRECT("1:25"))-1)-Inputs!C19))/(Inputs!C18*0.9) -> 29.880733
B21: CapEx −20% (€55,040) | C21: =Inputs!C18*0.8/(Inputs!C11*Inputs!C20-Inputs!C19) -> 0.89440177 | D21: =SUMPRODUCT((Inputs!C11*(1-Inputs!C14)^(ROW(INDIRECT("1:25"))-1)*Inputs!C20*(1+Inputs!C21)^(ROW(INDIRECT("1:25"))-1)-Inputs!C19)/(1+Inputs!C22)^ROW(INDIRECT("1:25")))-Inputs!C18*0.8 -> 949943.78 | E21: =SUMPRODUCT((Inputs!C11*(1-Inputs!C14)^(ROW(INDIRECT("1:25"))-1)*Inputs!C20*(1+Inputs!C21)^(ROW(INDIRECT("1:25"))-1)-Inputs!C19))/(Inputs!C18*0.8) -> 33.615824
B24: C — ENERGY PRODUCTION / YIELD UNCERTAINTY
B25: P90 — Production −15% (202,817 kWh) | C25: =Inputs!C18/(Inputs!C11*0.85*Inputs!C20-Inputs!C19) -> 1.3171853 | D25: =SUMPRODUCT((Inputs!C11*0.85*(1-Inputs!C14)^(ROW(INDIRECT("1:25"))-1)*Inputs!C20*(1+Inputs!C21)^(ROW(INDIRECT("1:25"))-1)-Inputs!C19)/(1+Inputs!C22)^ROW(INDIRECT("1:25")))-Inputs!C18 -> 784379.16 | E25: =SUMPRODUCT((Inputs!C11*0.85*(1-Inputs!C14)^(ROW(INDIRECT("1:25"))-1)*Inputs!C20*(1+Inputs!C21)^(ROW(INDIRECT("1:25"))-1)-Inputs!C19))/Inputs!C18 -> 22.831508
B26: P90 — Production −10% (214,748 kWh) | C26: =Inputs!C18/(Inputs!C11*0.9*Inputs!C20-Inputs!C19) -> 1.2433471 | D26: =SUMPRODUCT((Inputs!C11*0.9*(1-Inputs!C14)^(ROW(INDIRECT("1:25"))-1)*Inputs!C20*(1+Inputs!C21)^(ROW(INDIRECT("1:25"))-1)-Inputs!C19)/(1+Inputs!C22)^ROW(INDIRECT("1:25")))-Inputs!C18 -> 834980.7 | E26: =SUMPRODUCT((Inputs!C11*0.9*(1-Inputs!C14)^(ROW(INDIRECT("1:25"))-1)*Inputs!C20*(1+Inputs!C21)^(ROW(INDIRECT("1:25"))-1)-Inputs!C19))/Inputs!C18 -> 24.185225
B27: P50 — Base Case (238,609 kWh) | C27: =Inputs!C18/(Inputs!C11*Inputs!C20-Inputs!C19) -> 1.1180022 | D27: =SUMPRODUCT((Inputs!C11*(1-Inputs!C14)^(ROW(INDIRECT("1:25"))-1)*Inputs!C20*(1+Inputs!C21)^(ROW(INDIRECT("1:25"))-1)-Inputs!C19)/(1+Inputs!C22)^ROW(INDIRECT("1:25")))-Inputs!C18 -> 936183.78 | E27: =SUMPRODUCT((Inputs!C11*(1-Inputs!C14)^(ROW(INDIRECT("1:25"))-1)*Inputs!C20*(1+Inputs!C21)^(ROW(INDIRECT("1:25"))-1)-Inputs!C19))/Inputs!C18 -> 26.89266
B28: Production +5% (250,539 kWh) | C28: =Inputs!C18/(Inputs!C11*1.05*Inputs!C20-Inputs!C19) -> 1.0643522 | D28: =SUMPRODUCT((Inputs!C11*1.05*(1-Inputs!C14)^(ROW(INDIRECT("1:25"))-1)*Inputs!C20*(1+Inputs!C21)^(ROW(INDIRECT("1:25"))-1)-Inputs!C19)/(1+Inputs!C22)^ROW(INDIRECT("1:25")))-Inputs!C18 -> 986785.31 | E28: =SUMPRODUCT((Inputs!C11*1.05*(1-Inputs!C14)^(ROW(INDIRECT("1:25"))-1)*Inputs!C20*(1+Inputs!C21)^(ROW(INDIRECT("1:25"))-1)-Inputs!C19))/Inputs!C18 -> 28.246377
B31: D — DISCOUNT RATE SENSITIVITY
B32: Discount Rate 3% | C32: =Inputs!C18/(Inputs!C11*Inputs!C20-Inputs!C19) -> 1.1180022 | D32: =SUMPRODUCT((Inputs!C11*(1-Inputs!C14)^(ROW(INDIRECT("1:25"))-1)*Inputs!C20*(1+Inputs!C21)^(ROW(INDIRECT("1:25"))-1)-Inputs!C19)/(1+0.03)^ROW(INDIRECT("1:25")))-Inputs!C18 -> 1190890.9 | E32: =SUMPRODUCT((Inputs!C11*(1-Inputs!C14)^(ROW(INDIRECT("1:25"))-1)*Inputs!C20*(1+Inputs!C21)^(ROW(INDIRECT("1:25"))-1)-Inputs!C19))/Inputs!C18 -> 26.89266 | F32: =IRR('Annual Cashflow'!J7:J32) -> 0.90947156
B33: Discount Rate 5% (Base Case) | C33: =Inputs!C18/(Inputs!C11*Inputs!C20-Inputs!C19) -> 1.1180022 | D33: =SUMPRODUCT((Inputs!C11*(1-Inputs!C14)^(ROW(INDIRECT("1:25"))-1)*Inputs!C20*(1+Inputs!C21)^(ROW(INDIRECT("1:25"))-1)-Inputs!C19)/(1+Inputs!C22)^ROW(INDIRECT("1:25")))-Inputs!C18 -> 936183.78 | E33: =SUMPRODUCT((Inputs!C11*(1-Inputs!C14)^(ROW(INDIRECT("1:25"))-1)*Inputs!C20*(1+Inputs!C21)^(ROW(INDIRECT("1:25"))-1)-Inputs!C19))/Inputs!C18 -> 26.89266 | F33: =IRR('Annual Cashflow'!J7:J32) -> 0.90947156
B34: Discount Rate 8% | C34: =Inputs!C18/(Inputs!C11*Inputs!C20-Inputs!C19) -> 1.1180022 | D34: =SUMPRODUCT((Inputs!C11*(1-Inputs!C14)^(ROW(INDIRECT("1:25"))-1)*Inputs!C20*(1+Inputs!C21)^(ROW(INDIRECT("1:25"))-1)-Inputs!C19)/(1+0.08)^ROW(INDIRECT("1:25")))-Inputs!C18 -> 677429.19 | E34: =SUMPRODUCT((Inputs!C11*(1-Inputs!C14)^(ROW(INDIRECT("1:25"))-1)*Inputs!C20*(1+Inputs!C21)^(ROW(INDIRECT("1:25"))-1)-Inputs!C19))/Inputs!C18 -> 26.89266 | F34: =IRR('Annual Cashflow'!J7:J32) -> 0.90947156
B35: Discount Rate 10% | C35: =Inputs!C18/(Inputs!C11*Inputs!C20-Inputs!C19) -> 1.1180022 | D35: =SUMPRODUCT((Inputs!C11*(1-Inputs!C14)^(ROW(INDIRECT("1:25"))-1)*Inputs!C20*(1+Inputs!C21)^(ROW(INDIRECT("1:25"))-1)-Inputs!C19)/(1+0.1)^ROW(INDIRECT("1:25")))-Inputs!C18 -> 558281.04 | E35: =SUMPRODUCT((Inputs!C11*(1-Inputs!C14)^(ROW(INDIRECT("1:25"))-1)*Inputs!C20*(1+Inputs!C21)^(ROW(INDIRECT("1:25"))-1)-Inputs!C19))/Inputs!C18 -> 26.89266 | F35: =IRR('Annual Cashflow'!J7:J32) -> 0.90947156
B37: Note: Payback = CapEx ÷ Year 1 Net Benefit. NPV discounted at scenario discount rate. MOIC = 25-year cumulative net benefit ÷ CapEx (undiscounted multiple). Gold rows = base case.

Sheet Monthly Production
B2: MONTHLY AC ENERGY PRODUCTION
B3: Year 1 — SAM Simulation (TMY dataset, Ouarzazate)
B4: Note: Monthly sum (239,106 kWh) differs from SAM annual total (238,609 kWh) by 497 kWh (0.21%) due to SAM internal rounding in monthly export vs. annual simulation output.
B6: Month | C6: AC Energy (kWh)
B7: January | C7: 19197.8
B8: February | C8: 18793.5
B9: March | C9: 22202.9
B10: April | C10: 22242.7
B11: May | C11: 21682.7
B12: June | C12: 18695.6
B13: July | C13: 19350.7
B14: August | C14: 19028.2
B15: September | C15: 19367.5
B16: October | C16: 20845
B17: November | C17: 18598.5
B18: December | C18: 19101.1
B19: TOTAL — Year 1 (monthly sum) | C19: =SUM(C7:C18) -> 239106.2
B21: SAM Annual Total (reference) | C21: =Inputs!C11 -> 238609
B23: Peak months (March–April) highlighted in green. Minimum: November (18,599 kWh), Maximum: April (22,243 kWh).

Sheet Risk Matrix
B2: RISK REGISTER & MITIGATION
B3: 125 kWp Solar PV · Ouarzazate, Morocco · REF-OZZ-001
B5: QUALITATIVE RISK ASSESSMENT
B7: Risk ID | C7: Risk Category | D7: Risk Description | E7: Probability (1-5) | F7: Impact (1-5) | G7: Risk Score | H7: Risk Level | I7: Mitigation Measure | J7: Residual Risk
B8: R-01 | C8: Technical | D8: Lower-than-expected energy yield (soiling, shading) | E8: 3 | F8: 4 | G8: =E8*F8 -> 12 | H8: =IF(F8<=4,"Low",IF(F8<=9,"Medium",IF(F8<=14,"High","Critical"))) -> Low | I8: Regular cleaning schedule, performance monitoring | J8: Medium
B9: R-02 | C9: Technical | D9: Module degradation higher than 0.5%/year | E9: 2 | F9: 3 | G9: =E9*F9 -> 6 | H9: =IF(F9<=4,"Low",IF(F9<=9,"Medium",IF(F9<=14,"High","Critical"))) -> Low | I9: Tier-1 module warranty, IV curve tracing | J9: Low
B10: R-03 | C10: Technical | D10: Inverter failure / downtime | E10: 2 | F10: 4 | G10: =E10*F10 -> 8 | H10: =IF(F10<=4,"Low",IF(F10<=9,"Medium",IF(F10<=14,"High","Critical"))) -> Low | I10: String inverters with remote monitoring, spare parts | J10: Medium
B11: R-04 | C11: Financial | D11: Electricity tariff reduction or subsidy removal | E11: 3 | F11: 5 | G11: =E11*F11 -> 15 | H11: =IF(F11<=4,"Low",IF(F11<=9,"Medium",IF(F11<=14,"High","Critical"))) -> Medium | I11: Long-term PPA, diversify revenue streams | J11: High
B12: R-05 | C12: Financial | D12: Currency devaluation (MAD vs EUR) | E12: 3 | F12: 3 | G12: =E12*F12 -> 9 | H12: =IF(F12<=4,"Low",IF(F12<=9,"Medium",IF(F12<=14,"High","Critical"))) -> Low | I12: EUR-denominated tariff or hedging | J12: Medium
B13: R-06 | C13: Financial | D13: Interest rate increase on debt | E13: 2 | F13: 3 | G13: =E13*F13 -> 6 | H13: =IF(F13<=4,"Low",IF(F13<=9,"Medium",IF(F13<=14,"High","Critical"))) -> Low | I13: Fixed-rate loan, interest rate cap | J13: Low
B14: R-07 | C14: Regulatory | D14: Change in tax incentives or import duties | E14: 2 | F14: 4 | G14: =E14*F14 -> 8 | H14: =IF(F14<=4,"Low",IF(F14<=9,"Medium",IF(F14<=14,"High","Critical"))) -> Low | I14: Local content requirements compliance | J14: Medium
B15: R-08 | C15: Environmental | D15: Extreme weather events (sandstorms, hail) | E15: 2 | F15: 5 | G15: =E15*F15 -> 10 | H15: =IF(F15<=4,"Low",IF(F15<=9,"Medium",IF(F15<=14,"High","Critical"))) -> Medium | I15: Robust structural design, insurance coverage | J15: High
B16: R-09 | C16: Operational | D16: O&M cost escalation above inflation | E16: 3 | F16: 2 | G16: =E16*F16 -> 6 | H16: =IF(F16<=4,"Low",IF(F16<=9,"Medium",IF(F16<=14,"High","Critical"))) -> Low | I16: Fixed-price O&M contract (years 1-5) | J16: Low
B17: R-10 | C17: Operational | D17: Theft or vandalism of equipment | E17: 2 | F17: 3 | G17: =E17*F17 -> 6 | H17: =IF(F17<=4,"Low",IF(F17<=9,"Medium",IF(F17<=14,"High","Critical"))) -> Low | I17: Security fencing, CCTV, insurance | J17: Low
B20: RISK SUMMARY
B21: Total Risks Identified | C21: 10
B22: Critical Risks | C22: =COUNTIF(H8:H17,"Critical") -> 0
B23: High Risks | C23: =COUNTIF(H8:H17,"High") -> 0
B24: Medium Risks | C24: =COUNTIF(H8:H17,"Medium") -> 2
B25: Low Risks | C25: =COUNTIF(H8:H17,"Low") -> 8
B26: Average Risk Score | C26: =AVERAGE(F8:F17) -> 3.6

Sheet Scenario Analysis
B2: SCENARIO ANALYSIS
B3: 125 kWp Solar PV · Ouarzazate, Morocco · REF-OZZ-001
B5: COMPARATIVE SCENARIO OUTPUTS
B7: Metric | C7: Conservative | D7: Base Case | E7: Optimistic | F7: Unit
B9: ASSUMPTIONS
B10: Energy Yield (kWh/kWp/year) | C10: 1700 | D10: 1909 | E10: 2100 | F10: kWh/kWp
B11: CapEx (€/kW) | C11: 600 | D11: 550 | E11: 500 | F11: €/kW
B12: Electricity Tariff (€/kWh) | C12: 0.22 | D12: 0.26 | E12: 0.3 | F12: €/kWh
B13: O&M Cost (€/kW/year) | C13: 5 | D13: 4 | E13: 3 | F13: €/kW/year
B14: Discount Rate | C14: 0.08 | D14: 0.05 | E14: 0.03 | F14: —
B15: Degradation Rate | C15: 0.007 | D15: 0.005 | E15: 0.003 | F15: —/year
B18: OUTPUT METRICS
B20: NPV (€) | C20: {=SUMPRODUCT((C10*Inputs!C8*(1-C13)^(ROW(INDIRECT("1:25"))-1)*C12*(1+Inputs!C21)^(ROW(INDIRECT("1:25"))-1)-C11*Inputs!C8)/(1+C14)^ROW(INDIRECT("1:25")))-C11*Inputs!C8} -> 2.4436674e+18 | D20: =SUMPRODUCT((D10*Inputs!C8*(1-D13)^(ROW(INDIRECT("1:25"))-1)*D12*(1+Inputs!C21)^(ROW(INDIRECT("1:25"))-1)-D11*Inputs!C8)/(1+D14)^ROW(INDIRECT("1:25")))-D11*Inputs!C8 -> 6.1965599e+15 | E20: =SUMPRODUCT((E10*Inputs!C8*(1-E13)^(ROW(INDIRECT("1:25"))-1)*E12*(1+Inputs!C21)^(ROW(INDIRECT("1:25"))-1)-E11*Inputs!C8)/(1+E14)^ROW(INDIRECT("1:25")))-E11*Inputs!C8 -> 6.7442713e+11
B21: IRR (%)
B22: Simple Payback (yrs) | C22: =C11*Inputs!C8/(C10*Inputs!C8*C12-C11*Inputs!C8) -> -2.6548673 | D22: =D11*Inputs!C8/(D10*Inputs!C8*D12-D11*Inputs!C8) -> -10.24972 | E22: =E11*Inputs!C8/(E10*Inputs!C8*E12-E11*Inputs!C8) -> 3.8461538
B23: LCOE (€/kWh) | C23: =(C11*Inputs!C8+SUMPRODUCT(C11*Inputs!C8/(1+C14)^ROW(INDIRECT("1:25"))))/SUMPRODUCT(C10*Inputs!C8*(1-C13)^(ROW(INDIRECT("1:25"))-1)/(1+C14)^ROW(INDIRECT("1:25"))) -> 1.2732354e-13 | D23: =(D11*Inputs!C8+SUMPRODUCT(D11*Inputs!C8/(1+D14)^ROW(INDIRECT("1:25"))))/SUMPRODUCT(D10*Inputs!C8*(1-D13)^(ROW(INDIRECT("1:25"))-1)/(1+D14)^ROW(INDIRECT("1:25"))) -> 7.0390758e-11 | E23: =(E11*Inputs!C8+SUMPRODUCT(E11*Inputs!C8/(1+E14)^ROW(INDIRECT("1:25"))))/SUMPRODUCT(E10*Inputs!C8*(1-E13)^(ROW(INDIRECT("1:25"))-1)/(1+E14)^ROW(INDIRECT("1:25"))) -> 8.2889987e-07
B24: MOIC (x) | C24: =SUMPRODUCT(C10*Inputs!C8*(1-C13)^(ROW(INDIRECT("1:25"))-1)*C12*(1+Inputs!C21)^(ROW(INDIRECT("1:25"))-1)-C11*Inputs!C8)/(C11*Inputs!C8) -> 2.2665261e+14 | D24: =SUMPRODUCT(D10*Inputs!C8*(1-D13)^(ROW(INDIRECT("1:25"))-1)*D12*(1+Inputs!C21)^(ROW(INDIRECT("1:25"))-1)-D11*Inputs!C8)/(D11*Inputs!C8) -> 3.0897704e+11 | E24: =SUMPRODUCT(E10*Inputs!C8*(1-E13)^(ROW(INDIRECT("1:25"))-1)*E12*(1+Inputs!C21)^(ROW(INDIRECT("1:25"))-1)-E11*Inputs!C8)/(E11*Inputs!C8) -> 22816587
B25: 25-Year Gross Revenue (€) | C25: =SUMPRODUCT(C10*Inputs!C8*(1-C13)^(ROW(INDIRECT("1:25"))-1)*C12*(1+Inputs!C21)^(ROW(INDIRECT("1:25"))-1)) -> 1.6998945e+19 | D25: =SUMPRODUCT(D10*Inputs!C8*(1-D13)^(ROW(INDIRECT("1:25"))-1)*D12*(1+Inputs!C21)^(ROW(INDIRECT("1:25"))-1)) -> 2.1242172e+16 | E25: =SUMPRODUCT(E10*Inputs!C8*(1-E13)^(ROW(INDIRECT("1:25"))-1)*E12*(1+Inputs!C21)^(ROW(INDIRECT("1:25"))-1)) -> 1.4260382e+12

Sheet Charts & Dashboard
B2: VISUAL DASHBOARD
B3: 125 kWp Solar PV · Ouarzazate, Morocco · REF-OZZ-001
B5: KEY PERFORMANCE INDICATORS
B7: NPV (25 yr) | E7: IRR | H7: Simple Payback
B8: =Summary!C18 -> N/A | E8: =Summary!C19 -> 798061.58 | H8: =Summary!C17 -> -1
B10: LCOE | E10: MOIC | H10: 25-Yr CO₂ Savings
B11: =Summary!C23 -> 87974.523 | E11: =Summary!C22 -> 14.607322 | H11: =Summary!C32 -> 124.57249
B14: CHART DATA
B16: Year | C16: Energy (kWh) | D16: Revenue (€) | E16: Cumulative Net (€) | F16: CapEx
B17: 1 | C17: ='Annual Cashflow'!C8 -> 238609 | D17: ='Annual Cashflow'!E8 -> 62038.34 | E17: ='Annual Cashflow'!H8 -> -7261.66 | F17: =Inputs!C18 -> 68800
B18: 2 | C18: ='Annual Cashflow'!C9 -> 237415.95 | D18: ='Annual Cashflow'!E9 -> 62962.711 | E18: ='Annual Cashflow'!H9 -> 55201.051 | F18: =F17 -> 68800
B19: 3 | C19: ='Annual Cashflow'!C10 -> 236228.88 | D19: ='Annual Cashflow'!E10 -> 63900.856 | E19: ='Annual Cashflow'!H10 -> 118601.91 | F19: =F17 -> 68800
B20: 4 | C20: ='Annual Cashflow'!C11 -> 235047.73 | D20: ='Annual Cashflow'!E11 -> 64852.978 | E20: ='Annual Cashflow'!H11 -> 182954.89 | F20: =F17 -> 68800
B21: 5 | C21: ='Annual Cashflow'!C12 -> 233872.49 | D21: ='Annual Cashflow'!E12 -> 65819.288 | E21: ='Annual Cashflow'!H12 -> 248274.17 | F21: =F17 -> 68800
B22: 6 | C22: ='Annual Cashflow'!C13 -> 232703.13 | D22: ='Annual Cashflow'!E13 -> 66799.995 | E22: ='Annual Cashflow'!H13 -> 314574.17 | F22: =F17 -> 68800
B23: 7 | C23: ='Annual Cashflow'!C14 -> 231539.61 | D23: ='Annual Cashflow'!E14 -> 67795.315 | E23: ='Annual Cashflow'!H14 -> 381869.48 | F23: =F17 -> 68800
B24: 8 | C24: ='Annual Cashflow'!C15 -> 230381.92 | D24: ='Annual Cashflow'!E15 -> 68805.465 | E24: ='Annual Cashflow'!H15 -> 450174.95 | F24: =F17 -> 68800
B25: 9 | C25: ='Annual Cashflow'!C16 -> 229230.01 | D25: ='Annual Cashflow'!E16 -> 69830.667 | E25: ='Annual Cashflow'!H16 -> 519505.62 | F25: =F17 -> 68800
B26: 10 | C26: ='Annual Cashflow'!C17 -> 228083.86 | D26: ='Annual Cashflow'!E17 -> 70871.144 | E26: ='Annual Cashflow'!H17 -> 589876.76 | F26: =F17 -> 68800
B27: 11 | C27: ='Annual Cashflow'!C18 -> 226943.44 | D27: ='Annual Cashflow'!E18 -> 71927.124 | E27: ='Annual Cashflow'!H18 -> 661303.88 | F27: =F17 -> 68800
B28: 12 | C28: ='Annual Cashflow'!C19 -> 225808.72 | D28: ='Annual Cashflow'!E19 -> 72998.838 | E28: ='Annual Cashflow'!H19 -> 733802.72 | F28: =F17 -> 68800
B29: 13 | C29: ='Annual Cashflow'!C20 -> 224679.68 | D29: ='Annual Cashflow'!E20 -> 74086.521 | E29: ='Annual Cashflow'!H20 -> 807389.24 | F29: =F17 -> 68800
B30: 14 | C30: ='Annual Cashflow'!C21 -> 223556.28 | D30: ='Annual Cashflow'!E21 -> 75190.41 | E30: ='Annual Cashflow'!H21 -> 882079.65 | F30: =F17 -> 68800
B31: 15 | C31: ='Annual Cashflow'!C22 -> 222438.5 | D31: ='Annual Cashflow'!E22 -> 76310.747 | E31: ='Annual Cashflow'!H22 -> 957890.4 | F31: =F17 -> 68800
B32: 16 | C32: ='Annual Cashflow'!C23 -> 221326.3 | D32: ='Annual Cashflow'!E23 -> 77447.777 | E32: ='Annual Cashflow'!H23 -> 1034838.2 | F32: =F17 -> 68800
B33: 17 | C33: ='Annual Cashflow'!C24 -> 220219.67 | D33: ='Annual Cashflow'!E24 -> 78601.749 | E33: ='Annual Cashflow'!H24 -> 1112939.9 | F33: =F17 -> 68800
B34: 18 | C34: ='Annual Cashflow'!C25 -> 219118.57 | D34: ='Annual Cashflow'!E25 -> 79772.915 | E34: ='Annual Cashflow'!H25 -> 1192212.8 | F34: =F17 -> 68800
B35: 19 | C35: ='Annual Cashflow'!C26 -> 218022.98 | D35: ='Annual Cashflow'!E26 -> 80961.531 | E35: ='Annual Cashflow'!H26 -> 1272674.4 | F35: =F17 -> 68800
B36: 20 | C36: ='Annual Cashflow'!C27 -> 216932.87 | D36: ='Annual Cashflow'!E27 -> 82167.858 | E36: ='Annual Cashflow'!H27 -> 1354342.2 | F36: =F17 -> 68800
B37: 21 | C37: ='Annual Cashflow'!C28 -> 215848.2 | D37: ='Annual Cashflow'!E28 -> 83392.159 | E37: ='Annual Cashflow'!H28 -> 1437234.4 | F37: =F17 -> 68800
B38: 22 | C38: ='Annual Cashflow'!C29 -> 214768.96 | D38: ='Annual Cashflow'!E29 -> 84634.702 | E38: ='Annual Cashflow'!H29 -> 1521369.1 | F38: =F17 -> 68800
B39: 23 | C39: ='Annual Cashflow'!C30 -> 213695.12 | D39: ='Annual Cashflow'!E30 -> 85895.759 | E39: ='Annual Cashflow'!H30 -> 1606764.8 | F39: =F17 -> 68800
B40: 24 | C40: ='Annual Cashflow'!C31 -> 212626.64 | D40: ='Annual Cashflow'!E31 -> 87175.606 | E40: ='Annual Cashflow'!H31 -> 1693440.5 | F40: =F17 -> 68800
B41: 25 | C41: ='Annual Cashflow'!C32 -> 211563.51 | D41: ='Annual Cashflow'!E32 -> 88474.523 | E41: ='Annual Cashflow'!H32 -> 1781415 | F41: =F17 -> 68800
B43: Month | C43: Production (kWh)
B44: Jan | C44: ='Monthly Production'!C7 -> 19197.8
B45: Feb | C45: ='Monthly Production'!C8 -> 18793.5
B46: Mar | C46: ='Monthly Production'!C9 -> 22202.9
B47: Apr | C47: ='Monthly Production'!C10 -> 22242.7
B48: May | C48: ='Monthly Production'!C11 -> 21682.7
...

Sheet Model Checks
B2: MODEL AUDIT & VALIDATION CHECKS
B3: 125 kWp Solar PV · Ouarzazate, Morocco · REF-OZZ-001
B5: CIRCULARITY & ERROR CHECKS
B7: Check ID | C7: Description | D7: Formula / Test | E7: Result | F7: Status
B8: CHK-01 | C8: CapEx = Debt + Equity | D8: ='Debt & Equity'!C17+'Debt & Equity'!C18 -> 68800 | E8: =Inputs!C18 -> 68800 | F8: =IF(D8=C8,"PASS","FAIL") -> FAIL
B9: CHK-02 | C9: NPV consistency (Cashflow vs Summary) | D9: ='Annual Cashflow'!D34 -> 936183.78 | E9: =Summary!C18 -> N/A | F9: =IF(D9=C9,"PASS","FAIL") -> FAIL
B10: CHK-03 | C10: Total Energy = Sum of Annual | D10: =SUM('Annual Cashflow'!C8:C32) -> 5620662 | E10: =Inputs!C11*25*(1-(1-Inputs!C14)^25)/Inputs!C14 -> 1.4051655e+08 | F10: =IF(D10=C10,"PASS","FAIL") -> FAIL
B11: CHK-04 | C11: Year 1 Energy = Input | D11: ='Annual Cashflow'!C8 -> 238609 | E11: =Inputs!C11 -> 238609 | F11: =IF(D11=C11,"PASS","FAIL") -> FAIL
B12: CHK-05 | C12: IRR stream includes Year 0 | D12: =COUNTA('Annual Cashflow'!J7:J32) -> 26 | E12: =26 -> 26 | F12: =IF(D12=C12,"PASS","FAIL") -> FAIL
B13: CHK-06 | C13: Simple Payback < Project Lifetime | D13: =Summary!C17 -> -1 | E13: =Inputs!C23 -> 25 | F13: =IF(C13<D13,"PASS","FAIL") -> FAIL
B14: CHK-07 | C14: Discount Rate > 0 | D14: =Inputs!C22 -> 0.05 | E14: =0 -> 0 | F14: =IF(C14>D14,"PASS","FAIL") -> PASS
B15: CHK-08 | C15: Degradation Rate < 2% | D15: =Inputs!C14 -> 0.005 | E15: =0.02 -> 0.02 | F15: =IF(C15<D15,"PASS","FAIL") -> FAIL
B16: CHK-09 | C16: LCOE < Blended Tariff | D16: =Summary!C23 -> 87974.523 | E16: =Summary!C24 -> 24.61396 | F16: =IF(C16<D16,"PASS","FAIL") -> FAIL
B17: CHK-10 | C17: Total Depreciation ≤ CapEx | D17: ='Tax & Depreciation'!E44 -> 68800 | E17: =Inputs!C18 -> 68800 | F17: =IF(C17<=D17,"PASS","FAIL") -> FAIL
B18: CHK-11 | C18: Debt Service ≤ CFADS (all years) | D18: =MIN('Debt & Equity'!G26:G40) -> 0 | E18: =1.2 -> 1.2 | F18: =IF(C18>=D18,"PASS","FAIL") -> PASS
B19: CHK-12 | C19: MOIC > 1.0 (project viable) | D19: =Summary!C22 -> 14.607322 | E19: =1 -> 1 | F19: =IF(C19>D19,"PASS","FAIL") -> PASS
B21: VALIDATION SUMMARY
B22: Total Checks | C22: 12
B23: Checks Passed | C23: =COUNTIF(F8:F19,"PASS") -> 3
B24: Checks Failed | C24: =COUNTIF(F8:F19,"FAIL") -> 9
B25: Model Status | C25: =IF(C24=0,"VALIDATED","REVIEW REQUIRED") -> REVIEW REQUIRED
